{"out":"","outerr":"Traceback (most recent call last):\n  File \"/Users/danny/Ardustat_Private/pithy/code/ardustat_cv.py\", line 48, in <module>\n    print n.sread()\n  File \"/Users/danny/Ardustat_Private/pithy/code/ardustat_class_0820.py\", line 35, in sread\n    foo = urllib2.urlopen(self.bread)\n  File \"/System/Library/Frameworks/Python.framework/Versions/2.7/lib/python2.7/urllib2.py\", line 127, in urlopen\n    return _opener.open(url, data, timeout)\n  File \"/System/Library/Frameworks/Python.framework/Versions/2.7/lib/python2.7/urllib2.py\", line 404, in open\n    response = self._open(req, data)\n  File \"/System/Library/Frameworks/Python.framework/Versions/2.7/lib/python2.7/urllib2.py\", line 422, in _open\n    '_open', req)\n  File \"/System/Library/Frameworks/Python.framework/Versions/2.7/lib/python2.7/urllib2.py\", line 382, in _call_chain\n    result = func(*args)\n  File \"/System/Library/Frameworks/Python.framework/Versions/2.7/lib/python2.7/urllib2.py\", line 1214, in http_open\n    return self.do_open(httplib.HTTPConnection, req)\n  File \"/System/Library/Frameworks/Python.framework/Versions/2.7/lib/python2.7/urllib2.py\", line 1184, in do_open\n    raise URLError(err)\nurllib2.URLError: <urlopen error [Errno 61] Connection refused>\n","images":[],"exec_time":376}